Workbook

Sheet Categoria x Puesto
A1: Column1 | B1: Category | C1: Workplace | D1: Location | E1: Department | F1: Type | G1: Salary
A2: 0 | B2: Business Analyst | C2: Remote | D2: United Kingdom | E2: Operations | F2: Full time | G2: =RANDBETWEEN(6500,12000) -> 10948
A3: 1 | B3: Business Analyst | C3: Remote | D3: Makati, Metro Manila, Philippines | E3: Aux HQ | F3: Full time | G3: =RANDBETWEEN(6500,12000) -> 9322
A4: 2 | B4: Business Analyst | C4: On-site | D4: Al-Dajeej, Al Farwaniyah Governorate, Kuwait | E4: PWC Technologies | F4: Full time | G4: =RANDBETWEEN(6500,12000) -> 9271
A5: 3 | B5: Business Analyst | C5: On-site | D5: London, England, United Kingdom | E5: Consultants, Advisory | F5: Full time | G5: =RANDBETWEEN(6500,12000) -> 7695
A6: 4 | B6: Business Analyst | C6: Remote | D6: United Kingdom | E6: Operations | F6: Full time | G6: =RANDBETWEEN(6500,12000) -> 11498
A7: 5 | B7: Business Analyst | C7: Remote | D7: Makati, Metro Manila, Philippines | E7: Aux HQ | F7: Full time | G7: =RANDBETWEEN(6500,12000) -> 10408
A8: 6 | B8: Business Analyst | C8: On-site | D8: Al-Dajeej, Al Farwaniyah Governorate, Kuwait | E8: PWC Technologies | F8: Full time | G8: =RANDBETWEEN(6500,12000) -> 7145
A9: 7 | B9: Business Analyst | C9: On-site | D9: London, England, United Kingdom | E9: Consultants, Advisory | F9: Full time | G9: =RANDBETWEEN(6500,12000) -> 10074
A10: 8 | B10: Business Analyst | C10: Remote | D10: London, England, United Kingdom | E10: Change & Innovation | G10: =RANDBETWEEN(6500,12000) -> 11959
A11: 9 | B11: Business Analyst | C11: Remote | D11: Makati, Metro Manila, Philippines | E11: Aux HQ | F11: Full time | G11: =RANDBETWEEN(6500,12000) -> 7901
A12: 10 | B12: Business Analyst | C12: On-site | D12: Islamabad, Islamabad Capital Territory, Pakistan | E12: Data & Strategy, Performance Analytics | F12: Full time | G12: =RANDBETWEEN(6500,12000) -> 7248
A13: 11 | B13: Business Analyst | C13: Remote | D13: United States | E13: Computer/Software | F13: Full time | G13: =RANDBETWEEN(6500,12000) -> 10616
A14: 12 | B14: Business Analyst | C14: Hybrid | D14: London, England, United Kingdom | E14: Corporate Affairs | F14: Full time | G14: =RANDBETWEEN(6500,12000) -> 7600
A15: 13 | B15: Business Analyst | C15: Hybrid | D15: London, England, United Kingdom | E15: Technology | F15: Full time | G15: =RANDBETWEEN(6500,12000) -> 11358
A16: 14 | B16: Business Analyst | C16: Hybrid | D16: Cary, North Carolina, United States | E16: 1 - Operations | F16: Full time | G16: =RANDBETWEEN(6500,12000) -> 11064
A17: 15 | B17: Business Analyst | C17: On-site | D17: Overland Park, Kansas, United States | E17: Consulting | F17: Contract | G17: =RANDBETWEEN(6500,12000) -> 8745
A18: 16 | B18: Business Analyst | C18: Remote | D18: Brookfield, Wisconsin, United States | E18: Security - Delivery | F18: Full time | G18: =RANDBETWEEN(6500,12000) -> 8294
A19: 17 | B19: Business Analyst | C19: On-site | D19: Islamabad, Islamabad Capital Territory, Pakistan | E19: Data & Strategy, Digital Analytics | F19: Full time | G19: =RANDBETWEEN(6500,12000) -> 6937
A20: 18 | B20: Business Analyst | C20: Remote | D20: London, England, United Kingdom | E20: Change & Innovation | G20: =RANDBETWEEN(6500,12000) -> 6904
A21: 19 | B21: Business Analyst | C21: Remote | D21: Makati, Metro Manila, Philippines | E21: Aux HQ | F21: Full time | G21: =RANDBETWEEN(6500,12000) -> 10045
A22: 20 | B22: Business Analyst | C22: On-site | D22: Islamabad, Islamabad Capital Territory, Pakistan | E22: Data & Strategy, Performance Analytics | F22: Full time | G22: =RANDBETWEEN(6500,12000) -> 7841
A23: 21 | B23: Business Analyst | C23: Remote | D23: United States | E23: Computer/Software | F23: Full time | G23: =RANDBETWEEN(6500,12000) -> 9121
A24: 22 | B24: Business Analyst | C24: Hybrid | D24: London, England, United Kingdom | E24: Corporate Affairs | F24: Full time | G24: =RANDBETWEEN(6500,12000) -> 11897
A25: 23 | B25: Business Analyst | C25: Hybrid | D25: London, England, United Kingdom | E25: Technology | F25: Full time | G25: =RANDBETWEEN(6500,12000) -> 7119
A26: 24 | B26: Business Analyst | C26: Hybrid | D26: Cary, North Carolina, United States | E26: 1 - Operations | F26: Full time | G26: =RANDBETWEEN(6500,12000) -> 8085
A27: 25 | B27: Business Analyst | C27: On-site | D27: Overland Park, Kansas, United States | E27: Consulting | F27: Contract | G27: =RANDBETWEEN(6500,12000) -> 8470
A28: 26 | B28: Business Analyst | C28: Remote | D28: Brookfield, Wisconsin, United States | E28: Security - Delivery | F28: Full time | G28: =RANDBETWEEN(6500,12000) -> 11679
A29: 27 | B29: Business Analyst | C29: On-site | D29: Islamabad, Islamabad Capital Territory, Pakistan | E29: Data & Strategy, Digital Analytics | F29: Full time | G29: =RANDBETWEEN(6500,12000) -> 10556
A30: 28 | B30: Business Analyst | C30: Remote | D30: Athens, Attica, Greece | E30: DELIV1 | F30: Full time | G30: =RANDBETWEEN(6500,12000) -> 10489
A31: 29 | B31: Business Analyst | C31: On-site | D31: Astana, Aqmola oblısı, Kazakhstan | E31: TECH | F31: Full time | G31: =RANDBETWEEN(6500,12000) -> 9857
A32: 30 | B32: Business Analyst | C32: On-site | D32: North West, England, United Kingdom | E32: Change+ | G32: =RANDBETWEEN(6500,12000) -> 8492
A33: 31 | B33: Business Analyst | C33: Hybrid | D33: Berlin, Berlin, Germany | E33: Business & Organization | G33: =RANDBETWEEN(6500,12000) -> 9767
A34: 32 | B34: Business Analyst | C34: Remote | D34: Washington, District of Columbia, United States | E34: Account Team | F34: Full time | G34: =RANDBETWEEN(6500,12000) -> 7497
A35: 33 | B35: Business Analyst | C35: On-site | D35: Boston, Massachusetts, United States | E35: Delivery | F35: Full time | G35: =RANDBETWEEN(6500,12000) -> 9576
A36: 34 | B36: Business Analyst | C36: On-site | D36: Orlando, Florida, United States | E36: Information Technology | F36: Full time | G36: =RANDBETWEEN(6500,12000) -> 7643
A37: 35 | B37: Business Analyst | C37: On-site | D37: London, England, United Kingdom | E37: Change+ | G37: =RANDBETWEEN(6500,12000) -> 9291
A38: 36 | B38: Business Analyst | C38: Remote | D38: Makati, Metro Manila, Philippines | E38: Aux HQ | F38: Full time | G38: =RANDBETWEEN(6500,12000) -> 10805
A39: 37 | B39: Business Analyst | C39: On-site | D39: Washington, District of Columbia, United States | E39: Labs | F39: Full time | G39: =RANDBETWEEN(6500,12000) -> 10977
A40: 38 | B40: Business Analyst | C40: Remote | D40: Athens, Attica, Greece | E40: DELIV1 | F40: Full time | G40: =RANDBETWEEN(6500,12000) -> 9608
...

Sheet Dashboard
A2: Salarios | L2: Contratos
A3: Puesto | B3: Suma de Salarios | L3: Tipo | M3: Cantidad
A4: UI/UX | B4: 1817457 | L4: Tiempo completo | M4: =COUNTIF('Categoria x Puesto'!F:F,"Full time") -> 846
A5: Data Scientist | B5: 1754188 | L5: Contract | M5: =COUNTIF('Categoria x Puesto'!F:F,"Contract") -> 39
A6: Software Developer | B6: 1708647 | L6: Medio Tiempo | M6: =COUNTIF('Categoria x Puesto'!F:F,"Part time") -> 10
A7: HR | B7: 1668752 | L7: Temporal | M7: =COUNTIF('Categoria x Puesto'!F:F,"Temporary") -> 13
A8: Business Analyst | B8: 1616854 | L8: Temps plein | M8: =COUNTIF('Categoria x Puesto'!F:F,"Temps plein") -> 4
A9: Cloud | B9: 1570771 | L9: Otros | M9: =COUNTIF('Categoria x Puesto'!F:F,"Other") -> 14
M22: Cantidad de Trabajos
M23: Puestos | N23: Cantidad
M24: UI/UX | N24: =COUNTIF(job_data_merged_1[[#All],[Category]],"UI/UX") -> 191
M25: Data Scientist | N25: =COUNTIF(job_data_merged_1[[#All],[Category]],"Data Scientist") -> 190
M26: Software Developer | N26: =COUNTIF(job_data_merged_1[[#All],[Category]],"Software Developer") -> 189
A27: Modalidad de Trabajo | M27: HR | N27: =COUNTIF(job_data_merged_1[[#All],[Category]],"HR") -> 180
A28: Puesto | B28: Remoto | C28: Presencial | D28: Híbrido | M28: Business Analyst | N28: =COUNTIF(job_data_merged_1[[#All],[Category]],"Business Analyst") -> 175
A29: Business Analyst | B29: =COUNTIFS('Categoria x Puesto'!B:B,"Business Analyst",'Categoria x Puesto'!C:C,"Remote") -> 44 | C29: =COUNTIFS(job_data_merged_1[[#All],[Category]],"Business Analyst",job_data_merged_1[[#All],[Workplace]],"On-site") -> 90 | D29: =COUNTIFS(job_data_merged_1[[#All],[Category]],"Business Analyst",job_data_merged_1[[#All],[Workplace]],"Hybrid") -> 38 | M29: Cloud | N29: =COUNTIF(job_data_merged_1[[#All],[Category]],"Cloud") -> 170
A30: Cloud | B30: =COUNTIFS('Categoria x Puesto'!B:B,"Cloud",'Categoria x Puesto'!C:C,"Remote") -> 65 | C30: =COUNTIFS(job_data_merged_1[[#All],[Category]],"Cloud",job_data_merged_1[[#All],[Workplace]],"On-site") -> 62 | D30: =COUNTIFS(job_data_merged_1[[#All],[Category]],"Cloud",job_data_merged_1[[#All],[Workplace]],"Hybrid") -> 33
A31: Data Scientist | B31: =COUNTIFS('Categoria x Puesto'!B:B,"Data Scientist",'Categoria x Puesto'!C:C,"Remote") -> 71 | C31: =COUNTIFS(job_data_merged_1[[#All],[Category]],"Data Scientist",job_data_merged_1[[#All],[Workplace]],"On-site") -> 83 | D31: =COUNTIFS(job_data_merged_1[[#All],[Category]],"Data Scientist",job_data_merged_1[[#All],[Workplace]],"Hybrid") -> 24
A32: HR | B32: =COUNTIFS('Categoria x Puesto'!B:B,"HR",'Categoria x Puesto'!C:C,"Remote") -> 56 | C32: =COUNTIFS(job_data_merged_1[[#All],[Category]],"HR",job_data_merged_1[[#All],[Workplace]],"On-site") -> 96 | D32: =COUNTIFS(job_data_merged_1[[#All],[Category]],"HR",job_data_merged_1[[#All],[Workplace]],"Hybrid") -> 20
A33: Software Developer | B33: =COUNTIFS('Categoria x Puesto'!B:B,"Software Developer",'Categoria x Puesto'!C:C,"Remote") -> 70 | C33: =COUNTIFS(job_data_merged_1[[#All],[Category]],"Software Developer",job_data_merged_1[[#All],[Workplace]],"On-site") -> 80 | D33: =COUNTIFS(job_data_merged_1[[#All],[Category]],"Software Developer",job_data_merged_1[[#All],[Workplace]],"Hybrid") -> 21
A34: UI/UX | B34: =COUNTIFS('Categoria x Puesto'!B:B,"UI/UX",'Categoria x Puesto'!C:C,"Remote") -> 107 | C34: =COUNTIFS(job_data_merged_1[[#All],[Category]],"UI/UX",job_data_merged_1[[#All],[Workplace]],"On-site") -> 50 | D34: =COUNTIFS(job_data_merged_1[[#All],[Category]],"UI/UX",job_data_merged_1[[#All],[Workplace]],"Hybrid") -> 25
